Workbook
Name allfacilities: Facilities!$F$1:$F$300
Name allfacilities: Facilities!$F$2:$F$300
Name Baringo: masterlist!$B$2:$B$18
Name county: masterlist!$A$2:$A$6
Name Kajiado: masterlist!$C$2:$C$36
Name Laikipia: masterlist!$D$2:$D$24
Name Nakuru: masterlist!$E$2:$E$106
Name prepnew: PrEP_NEW!$A$2:$AD$58
Name prepnew: TX_HIV_HTN!$A$2:$AD$58
Name prepnew: PrEP_NEW!$A$2:$AD$58
Name Samburu: masterlist!$F$2:$F$13

Sheet ward
A1: County | B1: SubCounty | C1: Ward | D1: Facility | E1: datimid | F1: datimname | G1: MflCode | H1: HTC Support Type | I1: Activity HVF | J1: Assigned to Who
A2: USAID Tujenge Jamii | B2: USAID Tujenge Jamii | C2: USAID Tujenge Jamii | D2: USAID Tujenge Jamii | E2: 11111 | F2: USAID Tujenge Jamii | G2: 11111 | H2: DSD | I2: 1 | J2: UTJ
A3: Nakuru | B3: Gilgil | C3: Gilgil | D3: =C3 -> Gilgil | E3: 10 | F3: =D3 -> Gilgil | G3: 10 | H3: DSD | I3: 1 | J3: Mbawi
A4: Nakuru | B4: Kuresoi South | C4: Keringet | D4: =C4 -> Keringet | E4: 38 | F4: =D4 -> Keringet | G4: 38 | H4: DSD | I4: 1
A5: Nakuru | B5: Molo | C5: Elburgon | D5: =C5 -> Elburgon | E5: 67 | F5: =D5 -> Elburgon | G5: 67 | H5: DSD | I5: 1
A6: Nakuru | B6: Molo | C6: Molo | D6: =C6 -> Molo | E6: 69 | F6: =D6 -> Molo | G6: 69 | H6: DSD | I6: 1
A7: Nakuru | B7: Naivasha | C7: Mai mahiu | D7: =C7 -> Mai mahiu | E7: 73 | F7: =D7 -> Mai mahiu | G7: 73 | H7: DSD | I7: 1
A8: Nakuru | B8: Naivasha | C8: Viwandani | D8: =C8 -> Viwandani | E8: 77 | F8: =D8 -> Viwandani | G8: 77 | H8: DSD | I8: 1
A9: Nakuru | B9: Nakuru East | C9: Biashara | D9: =C9 -> Biashara | E9: 78 | F9: =D9 -> Biashara | G9: 78 | H9: DSD | I9: 1
A10: Nakuru | B10: Nakuru West | C10: London | D10: =C10 -> London | E10: 81 | F10: =D10 -> London | G10: 81 | H10: DSD | I10: 1
A11: Nakuru | B11: Njoro | C11: Mau narok | D11: =C11 -> Mau narok | E11: 117 | F11: =D11 -> Mau narok | G11: 117 | H11: DSD | I11: 1
A12: Nakuru | B12: Rongai | C12: Mosop | D12: =C12 -> Mosop | E12: 128 | F12: =D12 -> Mosop | G12: 128 | H12: DSD | I12: 1
A13: Nakuru | B13: Rongai | C13: Visoi | D13: =C13 -> Visoi | E13: 131 | F13: =D13 -> Visoi | G13: 131 | H13: DSD | I13: 1

Sheet Prevention
B2: Facility Name: | D2: USAID Tujenge Jamii | H2: =IFERROR(VLOOKUP(D2,Facilities!F1:H300,2,FALSE),"") | I2: Support Type | L2: ='Testing Path 2 - HTS TST Mod'!K2 | N2: Period | O2: =VMMC_CIRC!A2 -> 0
B3: =CONCATENATE(L2,": VMMC_CIRC") -> : VMMC_CIRC
B4: Auto-Calculate | D4: Number of males circumcised as part of the voluntary medical male circumcision (VMMC) for HIV prevention program within the reporting period. Numerator will auto-calculate from the Age Disaggregates. | R4: {=_xlfn.UNIQUE(VMMC_CIRC!D2:D4)} -> #NAME?
B7: Numerator | D7: =IF(SUM(C12:P12)=0,"subtotal",SUM(C12:P12)) -> subtotal
B9: Required | D9: Disaggregated by Age
C11: Unknown Age | D11: <60 Days | E11: 2mo-1yr | F11: 1-4 | G11: 5-9 | H11: 10-14 | I11: 15-19 | J11: 20-24 | K11: 25-29 | L11: 30-34 | M11: 35-39 | N11: 40-44 | O11: 45-49 | P11: 50+
C12: {=SUMPRODUCT(($H$2=VMMC_CIRC!$E$2:$E$33)*(VMMC_CIRC!H$2:H$33))} -> 0 | D12: {=SUMPRODUCT(($H$2=VMMC_CIRC!$E$2:$E$33)*(VMMC_CIRC!I$2:I$33))} -> 0 | E12: {=SUMPRODUCT(($H$2=VMMC_CIRC!$E$2:$E$33)*(VMMC_CIRC!J$2:J$33))} -> 0 | F12: {=SUMPRODUCT(($H$2=VMMC_CIRC!$E$2:$E$33)*(VMMC_CIRC!K$2:K$33))} -> 0 | G12: {=SUMPRODUCT(($H$2=VMMC_CIRC!$E$2:$E$33)*(VMMC_CIRC!L$2:L$33))} -> 0 | H12: {=SUMPRODUCT(($H$2=VMMC_CIRC!$E$2:$E$33)*(VMMC_CIRC!M$2:M$33))} -> 0 | I12: {=SUMPRODUCT(($H$2=VMMC_CIRC!$E$2:$E$33)*(VMMC_CIRC!N$2:N$33))} -> 0 | J12: {=SUMPRODUCT(($H$2=VMMC_CIRC!$E$2:$E$33)*(VMMC_CIRC!O$2:O$33))} -> 0 | ... P12: {=SUMPRODUCT(($H$2=VMMC_CIRC!$E$2:$E$33)*(VMMC_CIRC!U$2:U$33))} -> 0
B15: Sub-total | D15: =IF(SUM(C12:P12)=0,"subtotal",SUM(C12:P12)) -> subtotal
B17: Required | D17: Disaggregated by HIV Status and Outcome
B18: Number of HIV-positive clients (tested HIV positive at VMMC site) | D18: Unknown Age | E18: <1 | F18: 1-4 | G18: 5-9 | H18: 10-14 | I18: 15-19 | J18: 20-24 | K18: 25-29 | L18: 30-34 | M18: 35-39 | N18: 40-44 | O18: 45-49 | P18: 50+
D19: {=SUMPRODUCT(($H$2=VMMC_CIRC!$E$2:$E$33)*(VMMC_CIRC!V$2:V$33))} -> 0 | E19: {=SUMPRODUCT(($H$2=VMMC_CIRC!$E$2:$E$33)*(VMMC_CIRC!W$2:W$33))} -> 0 | F19: {=SUMPRODUCT(($H$2=VMMC_CIRC!$E$2:$E$33)*(VMMC_CIRC!X$2:X$33))} -> 0 | G19: {=SUMPRODUCT(($H$2=VMMC_CIRC!$E$2:$E$33)*(VMMC_CIRC!Y$2:Y$33))} -> 0 | H19: {=SUMPRODUCT(($H$2=VMMC_CIRC!$E$2:$E$33)*(VMMC_CIRC!Z$2:Z$33))} -> 0 | I19: {=SUMPRODUCT(($H$2=VMMC_CIRC!$E$2:$E$33)*(VMMC_CIRC!AA$2:AA$33))} -> 0 | J19: {=SUMPRODUCT(($H$2=VMMC_CIRC!$E$2:$E$33)*(VMMC_CIRC!AB$2:AB$33))} -> 0 | K19: {=SUMPRODUCT(($H$2=VMMC_CIRC!$E$2:$E$33)*(VMMC_CIRC!AC$2:AC$33))} -> 0 | ... P19: {=SUMPRODUCT(($H$2=VMMC_CIRC!$E$2:$E$33)*(VMMC_CIRC!AH$2:AH$33))} -> 0
B21: Number of HIV-negative clients (tested HIV negative at VMMC site) | D21: Unknown Age | E21: <1 | F21: 1-4 | G21: 5-9 | H21: 10-14 | I21: 15-19 | J21: 20-24 | K21: 25-29 | L21: 30-34 | M21: 35-39 | N21: 40-44 | O21: 45-49 | P21: 50+
D22: {=SUMPRODUCT(($H$2=VMMC_CIRC!$E$2:$E$33)*(VMMC_CIRC!AI$2:AI$33))} -> 0 | E22: {=SUMPRODUCT(($H$2=VMMC_CIRC!$E$2:$E$33)*(VMMC_CIRC!AJ$2:AJ$33))} -> 0 | F22: {=SUMPRODUCT(($H$2=VMMC_CIRC!$E$2:$E$33)*(VMMC_CIRC!AK$2:AK$33))} -> 0 | G22: {=SUMPRODUCT(($H$2=VMMC_CIRC!$E$2:$E$33)*(VMMC_CIRC!AL$2:AL$33))} -> 0 | H22: {=SUMPRODUCT(($H$2=VMMC_CIRC!$E$2:$E$33)*(VMMC_CIRC!AM$2:AM$33))} -> 0 | I22: {=SUMPRODUCT(($H$2=VMMC_CIRC!$E$2:$E$33)*(VMMC_CIRC!AN$2:AN$33))} -> 0 | J22: {=SUMPRODUCT(($H$2=VMMC_CIRC!$E$2:$E$33)*(VMMC_CIRC!AO$2:AO$33))} -> 0 | K22: {=SUMPRODUCT(($H$2=VMMC_CIRC!$E$2:$E$33)*(VMMC_CIRC!AP$2:AP$33))} -> 0 | ... P22: {=SUMPRODUCT(($H$2=VMMC_CIRC!$E$2:$E$33)*(VMMC_CIRC!AU$2:AU$33))} -> 0
B24: Number of clients with indeterminate HIV status or not tested for HIV at site (regardless of previous documentation) | D24: Unknown Age | E24: <1 | F24: 1-4 | G24: 5-9 | H24: 10-14 | I24: 15-19 | J24: 20-24 | K24: 25-29 | L24: 30-34 | M24: 35-39 | N24: 40-44 | O24: 45-49 | P24: 50+
D25: {=SUMPRODUCT(($H$2=VMMC_CIRC!$E$2:$E$33)*(VMMC_CIRC!AV$2:AV$33))} -> 0 | E25: {=SUMPRODUCT(($H$2=VMMC_CIRC!$E$2:$E$33)*(VMMC_CIRC!AW$2:AW$33))} -> 0 | F25: {=SUMPRODUCT(($H$2=VMMC_CIRC!$E$2:$E$33)*(VMMC_CIRC!AX$2:AX$33))} -> 0 | G25: {=SUMPRODUCT(($H$2=VMMC_CIRC!$E$2:$E$33)*(VMMC_CIRC!AY$2:AY$33))} -> 0 | H25: {=SUMPRODUCT(($H$2=VMMC_CIRC!$E$2:$E$33)*(VMMC_CIRC!AZ$2:AZ$33))} -> 0 | I25: {=SUMPRODUCT(($H$2=VMMC_CIRC!$E$2:$E$33)*(VMMC_CIRC!BA$2:BA$33))} -> 0 | J25: {=SUMPRODUCT(($H$2=VMMC_CIRC!$E$2:$E$33)*(VMMC_CIRC!BB$2:BB$33))} -> 0 | K25: {=SUMPRODUCT(($H$2=VMMC_CIRC!$E$2:$E$33)*(VMMC_CIRC!BC$2:BC$33))} -> 0 | ... P25: {=SUMPRODUCT(($H$2=VMMC_CIRC!$E$2:$E$33)*(VMMC_CIRC!BH$2:BH$33))} -> 0
B28: Sub-total | D28: =IF(SUM(D19:P19,D22:P22,D25:P25)=0,"subtotal",SUM(D19:P19,D22:P22,D25:P25)) -> subtotal
B30: Required | D30: Disaggregated by Circumcision Technique / Follow-up Status
D31: Technique | J31: Follow-up Status:
F32: Within 14 days of surgery | J32: NOT within 14 days, or did not follow-up within reporting period.
B33: Surgical VMMC | D33: {=SUMPRODUCT(($H$2=VMMC_CIRC!$E$2:$E$33)*(VMMC_CIRC!BI$2:BI$33))} -> 0 | G33: {=SUMPRODUCT(($H$2=VMMC_CIRC!$E$2:$E$33)*(VMMC_CIRC!BJ$2:BJ$33))} -> 0 | K33: {=SUMPRODUCT(($H$2=VMMC_CIRC!$E$2:$E$33)*(VMMC_CIRC!BK$2:BK$33))} -> 0
F35: Within 14 days of device placement. May include device removal. | J35: NOT within 14 days, or did not follow-up within reporting period.
B36: Device-based VMMC | D36: {=SUMPRODUCT(($H$2=VMMC_CIRC!$E$2:$E$33)*(VMMC_CIRC!BL$2:BL$33))} -> 0 | G36: {=SUMPRODUCT(($H$2=VMMC_CIRC!$E$2:$E$33)*(VMMC_CIRC!BM$2:BM$33))} -> 0 | K36: {=SUMPRODUCT(($H$2=VMMC_CIRC!$E$2:$E$33)*(VMMC_CIRC!BN$2:BN$33))} -> 0
B39: Sub-total | D39: =IF(SUM(D33,D36)=0,"subtotal",SUM(D33,D36)) -> subtotal | G39: =IF(SUM(G33,G36)=0,"subtotal",SUM(G33,G36)) -> subtotal | K39: =IF(SUM(K33,K36)=0,"subtotal",SUM(K33,K36)) -> subtotal
B46: Facility Name: | D46: =D2 -> USAID Tujenge Jamii | I46: Support Type | L46: ='Testing Path 2 - HTS TST Mod'!K2 | N46: Period | O46: =PrEP_NEW!A2 -> 0
B48: If MER Results data is unable to be disaggregated by DSD or TA support type, please report ALL data under the TA Support Type.
B50: =CONCATENATE(L46,": PrEP_NEW") -> : PrEP_NEW
B51: Auto-Calculate | D51: Number of individuals who have been newly enrolled on oral antiretroviral pre-exposure prophylaxis (PrEP) in the reporting period to prevent HIV infection. Numerator will auto-calculate from the Age/Sex Disaggregates.
B54: Numerator | D54: =IF(SUM(D58:L58,D61:L61)=0,"subtotal",SUM(D58:L58,D61:L61)) -> subtotal
B56: Required | D56: Disaggregated by Age / Sex
D57: Unknown Age | E57: 15-19 | F57: 20-24 | G57: 25-29 | H57: 30-34 | I57: 35-39 | J57: 40-44 | K57: 45-49 | L57: 50+
B58: Female | D58: {=SUMPRODUCT(($H$2=PrEP_NEW!$E$2:$E$350)*(PrEP_NEW!G$2:G$350))} -> 0 | E58: {=SUMPRODUCT(($H$2=PrEP_NEW!$E$2:$E$350)*(PrEP_NEW!H$2:H$350))} -> 0 | F58: {=SUMPRODUCT(($H$2=PrEP_NEW!$E$2:$E$350)*(PrEP_NEW!I$2:I$350))} -> 0 | G58: {=SUMPRODUCT(($H$2=PrEP_NEW!$E$2:$E$350)*(PrEP_NEW!J$2:J$350))} -> 0 | H58: {=SUMPRODUCT(($H$2=PrEP_NEW!$E$2:$E$350)*(PrEP_NEW!K$2:K$350))} -> 0 | I58: {=SUMPRODUCT(($H$2=PrEP_NEW!$E$2:$E$350)*(PrEP_NEW!L$2:L$350))} -> 0 | J58: {=SUMPRODUCT(($H$2=PrEP_NEW!$E$2:$E$350)*(PrEP_NEW!M$2:M$350))} -> 0 | K58: {=SUMPRODUCT(($H$2=PrEP_NEW!$E$2:$E$350)*(PrEP_NEW!N$2:N$350))} -> 0 | L58: {=SUMPRODUCT(($H$2=PrEP_NEW!$E$2:$E$350)*(PrEP_NEW!O$2:O$350))} -> 0 | M58: =IF(SUM(D58:L58)=0,"subtotal",SUM(D58:L58)) -> subtotal
D60: Unknown Age | E60: 15-19 | F60: 20-24 | G60: 25-29 | H60: 30-34 | I60: 35-39 | J60: 40-44 | K60: 45-49 | L60: 50+
B61: Male | D61: {=SUMPRODUCT(($H$2=PrEP_NEW!$E$2:$E$350)*(PrEP_NEW!Q$2:Q$350))} -> 0 | E61: {=SUMPRODUCT(($H$2=PrEP_NEW!$E$2:$E$350)*(PrEP_NEW!R$2:R$350))} -> 0 | F61: {=SUMPRODUCT(($H$2=PrEP_NEW!$E$2:$E$350)*(PrEP_NEW!S$2:S$350))} -> 0 | G61: {=SUMPRODUCT(($H$2=PrEP_NEW!$E$2:$E$350)*(PrEP_NEW!T$2:T$350))} -> 0 | H61: {=SUMPRODUCT(($H$2=PrEP_NEW!$E$2:$E$350)*(PrEP_NEW!U$2:U$350))} -> 0 | I61: {=SUMPRODUCT(($H$2=PrEP_NEW!$E$2:$E$350)*(PrEP_NEW!V$2:V$350))} -> 0 | J61: {=SUMPRODUCT(($H$2=PrEP_NEW!$E$2:$E$350)*(PrEP_NEW!W$2:W$350))} -> 0 | K61: {=SUMPRODUCT(($H$2=PrEP_NEW!$E$2:$E$350)*(PrEP_NEW!X$2:X$350))} -> 0 | L61: {=SUMPRODUCT(($H$2=PrEP_NEW!$E$2:$E$350)*(PrEP_NEW!Y$2:Y$350))} -> 0 | M61: =IF(SUM(D61:L61)=0,"subtotal",SUM(D61:L61)) -> subtotal
B63: Required | E63: Disaggregated by key population type: Data on key populations should be reported in both the "Disaggregated by key population type" section and the "Disaggregated by Age/Sex" section.
B65: PWID | G65: {=SUMPRODUCT(($H$2=PrEP_NEW!$E$2:$E$350)*(PrEP_NEW!AB$2:AB$350))} -> 0
B68: MSM | G68: {=SUMPRODUCT(($H$2=PrEP_NEW!$E$2:$E$350)*(PrEP_NEW!AC$2:AC$350))} -> 0
B71: Transgender People | G71: {=SUMPRODUCT(($H$2=PrEP_NEW!$E$2:$E$350)*(PrEP_NEW!AD$2:AD$350))} -> 0
B74: FSW | G74: {=SUMPRODUCT(($H$2=PrEP_NEW!$E$2:$E$350)*(PrEP_NEW!AE$2:AE$350))} -> 0
B77: People in prison and other closed settings | G77: =SUMPRODUCT(($H$2=PrEP_NEW!$E$2:$E$350)*(PrEP_NEW!AF$2:AF$350)) -> 0
B79: Optional | E79: Disaggregated by Pregnant/Breastfeeding Status: Data on Pregnant/Breastfeeding individuals should be reported in both the "Disaggregated by Pregnant/Breastfeeding" section and the "Disaggregated by Age/Sex" section.
...

Sheet VMMC_CIRC
A1: period | B1: County | C1: Sub County | D1: Health Facility | E1: MFL Code | F1: Support Type | G1: Numerator | H1: Unknown Age | I1: <60 Days | J1: 2 Mo-1 Y | K1: 1-4 Y | L1: 5-9 Y | M1: 10-14 Y | N1: 15-19 Y | O1: 20-24 Y | P1: 25-29 Y | Q1: 30-34 Y | R1: 35-39 Y | S1: 40-44 Y | T1: 45-49 Y | U1: 50+ Y | V1: hivpos Unknown Age | W1: hivpos <1 Y | X1: hivpos 1-4 Y | Y1: hivpos 5-9 Y | Z1: hivpos 10-14 Y | AA1: hivpos 15-19 Y | AB1: hivpos 20-24 Y | AC1: hivpos 25-29 Y | AD1: hivpos 30-34 Y | AE1: hivpos 35-39 Y | AF1: hivpos 40-44 Y | AG1: hivpos 45-49 Y | AH1: hivpos 50+ Y | AI1: hivneg Unknown Age | AJ1: hivneg <1 Y | AK1: hivneg 1-4 Y | AL1: hivneg 5-9 Y | AM1: hivneg 10-14 Y | AN1: hivneg 15-19 Y | AO1: hivneg 20-24 Y | AP1: hivneg 25-29 Y | AQ1: hivneg 30-34 Y | AR1: hivneg 35-39 Y | AS1: hivneg 40-44 Y | AT1: hivneg 45-49 Y | AU1: hivneg50+ Y | AV1: not tested Unknown Age | AW1: not tested <1 Y | AX1: not tested 1-4 Y | AY1: not tested 5-9 Y | AZ1: not tested 10-14 Y | BA1: not tested 15-19 Y | BB1: not tested 20-24 Y | BC1: not tested 25-29 Y | BD1: not tested 30-34 Y | BE1: not tested 35-39 Y | BF1: not tested 40-44 Y | BG1: not tested 45-49 Y | BH1: not tested 50+ Y | BI1: Surgical VMMC | BJ1: Returned for postoperative follow-up care within 14 days of surgery | BK1: Did not return for postoperative follow-up care within 14 days of surgery | BL1: Device-Based VMMC | BM1: Within 14 days of device placement. May include device removal | BN1: NOT within 14 days, or did not follow-up within reporting period
A20: =A4 -> 0 | B20: USAID Tujenge Jamii | C20: USAID Tujenge Jamii | D20: USAID Tujenge Jamii | E20: 11111 | F20: DSD | G20: =SUM(G2:G19) -> 0 | H20: =SUM(H2:H19) -> 0 | I20: =SUM(I2:I19) -> 0 | J20: =SUM(J2:J19) -> 0 | K20: =SUM(K2:K19) -> 0 | L20: =SUM(L2:L19) -> 0 | M20: =SUM(M2:M19) -> 0 | N20: =SUM(N2:N19) -> 0 | ... BN20: =SUM(BN2:BN19) -> 0

Sheet PrEP_NEW
A1: period | B1: County | C1: sub_county | D1: Facility | E1: MFLCode | F1: Support Type | G1: Unkown F | H1: 15-19 F | I1: 20-24 F | J1: 25-29 F | K1: 30-34 F | L1: 35-39 F | M1: 40-44 F | N1: 45-49 F | O1: 50+ F | P1: Total Female | Q1: Unkown M | R1: 15-19 M | S1: 20-24 M | T1: 25-29 M | U1: 30-34 M | V1: 35-39 M | W1: 40-44 M | X1: 45-49 M | Y1: 50+ M | Z1: Total Male | AA1: Total | AB1: People who inject drugs PWID | AC1: Men who have sex with men MSM | AD1: Transgender people TG | AE1: Female sex workers FSW | AF1: People in prison and other closed settings | AG1: Pregnant | AH1: Breastfeeding | AI1: Prep_dist_Facility | AJ1: Prep_dist_Community | AK1: Prep_Type_Oral | AL1: Prep_Type_injectable | AM1: Prep_Type_other | AN1: ART High Volume | AO1: HTC High Volume | AP1: PMTCT High Volume | AQ1: Num vs KP Validation | AR1: Picked Site
AQ2: =AA2-SUM(AB2:AF2) -> 0 | AR2: =IF(AQ2<0,D2&",","")
AQ3: =AA3-SUM(AB3:AF3) -> 0 | AR3: =IF(AQ3<0,D3&",","")
AQ4: =AA4-SUM(AB4:AF4) -> 0 | AR4: =IF(AQ4<0,D4&",","")
AQ5: =AA5-SUM(AB5:AF5) -> 0 | AR5: =IF(AQ5<0,D5&",","")
AQ6: =AA6-SUM(AB6:AF6) -> 0 | AR6: =IF(AQ6<0,D6&",","")
AQ7: =AA7-SUM(AB7:AF7) -> 0 | AR7: =IF(AQ7<0,D7&",","")
AQ8: =AA8-SUM(AB8:AF8) -> 0 | AR8: =IF(AQ8<0,D8&",","")
AQ9: =AA9-SUM(AB9:AF9) -> 0 | AR9: =IF(AQ9<0,D9&",","")
AQ10: =AA10-SUM(AB10:AF10) -> 0 | AR10: =IF(AQ10<0,D10&",","")
AQ11: =AA11-SUM(AB11:AF11) -> 0 | AR11: =IF(AQ11<0,D11&",","")
AQ12: =AA12-SUM(AB12:AF12) -> 0 | AR12: =IF(AQ12<0,D12&",","")
AQ13: =AA13-SUM(AB13:AF13) -> 0 | AR13: =IF(AQ13<0,D13&",","")
... AQ349: =AA349-SUM(AB349:AF349) -> 0 | AR349: =IF(AQ349<0,D349&",","")
A350: =A2 -> 0 | B350: USAID Tujenge Jamii | C350: USAID Tujenge Jamii | D350: USAID Tujenge Jamii | E350: 11111 | F350: DSD | G350: =SUM(G2:G349) -> 0 | H350: =SUM(H2:H349) -> 0 | I350: =SUM(I2:I349) -> 0 | J350: =SUM(J2:J349) -> 0 | K350: =SUM(K2:K349) -> 0 | L350: =SUM(L2:L349) -> 0 | M350: =SUM(M2:M349) -> 0 | N350: =SUM(N2:N349) -> 0 | ... AM350: =SUM(AM2:AM349) -> 0 | AN350: 1 | AO350: 1 | AP350: 1 | AQ350: =SUM(AB350:AF350)-AA350 -> 0

Sheet PrEP_CT
A1: period | B1: County | C1: sub_county | D1: Facility | E1: MFLCode | F1: Support Type | G1: Unkown F | H1: 15-19 F | I1: 20-24 F | J1: 25-29 F | K1: 30-34 F | L1: 35-39 F | M1: 40-44 F | N1: 45-49 F | O1: 50+ F | P1: Total Female | Q1: Unkown M | R1: 15-19 M | S1: 20-24 M | T1: 25-29 M | U1: 30-34 M | V1: 35-39 M | W1: 40-44 M | X1: 45-49 M | Y1: 50+ M | Z1: Total Male | AA1: Total | AB1: Positive | AC1: Negative | AD1: Other | AE1: People who inject drugs PWID | AF1: Men who have sex with men MSM | AG1: Transgender people TG | AH1: Female sex workers FSW | AI1: People in prison and other closed settings | AJ1: Pregnant | AK1: Breastfeeding | AL1: Prep_dist_Facility | AM1: Prep_dist_Community | AN1: Prep_Type_Oral | AO1: Prep_Type_injectable | AP1: Prep_Type_other | AQ1: ART High Volume | AR1: HTC High Volume | AS1: PMTCT High Volume | AT1: Num vs KP Validation | AU1: Picked Site
AT2: =AA2-SUM(AE2:AI2) -> 0 | AU2: =IF(AT2<0,$D2&",","")
AT3: =AA3-SUM(AE3:AI3) -> 0 | AU3: =IF(AT3<0,$D3&",","")
AT4: =AA4-SUM(AE4:AI4) -> 0 | AU4: =IF(AT4<0,$D4&",","")
AT5: =AA5-SUM(AE5:AI5) -> 0 | AU5: =IF(AT5<0,$D5&",","")
AT6: =AA6-SUM(AE6:AI6) -> 0 | AU6: =IF(AT6<0,$D6&",","")
AT7: =AA7-SUM(AE7:AI7) -> 0 | AU7: =IF(AT7<0,$D7&",","")
AT8: =AA8-SUM(AE8:AI8) -> 0 | AU8: =IF(AT8<0,$D8&",","")
AT9: =AA9-SUM(AE9:AI9) -> 0 | AU9: =IF(AT9<0,$D9&",","")
AT10: =AA10-SUM(AE10:AI10) -> 0 | AU10: =IF(AT10<0,$D10&",","")
AT11: =AA11-SUM(AE11:AI11) -> 0 | AU11: =IF(AT11<0,$D11&",","")
AT12: =AA12-SUM(AE12:AI12) -> 0 | AU12: =IF(AT12<0,$D12&",","")
AT13: =AA13-SUM(AE13:AI13) -> 0 | AU13: =IF(AT13<0,$D13&",","")
... AT349: =AA349-SUM(AE349:AI349) -> 0 | AU349: =IF(AT349<0,$D349&",","")
A350: =A2 -> 0 | B350: USAID Tujenge Jamii | C350: USAID Tujenge Jamii | D350: USAID Tujenge Jamii | E350: 11111 | F350: DSD | G350: =SUM(G2:G349) -> 0 | H350: =SUM(H2:H349) -> 0 | I350: =SUM(I2:I349) -> 0 | J350: =SUM(J2:J349) -> 0 | K350: =SUM(K2:K349) -> 0 | L350: =SUM(L2:L349) -> 0 | M350: =SUM(M2:M349) -> 0 | N350: =SUM(N2:N349) -> 0 | ... AP350: =SUM(AP2:AP349) -> 0 | AQ350: 1 | AR350: 1 | AS350: 1 | AT350: =AA350-SUM(AE350:AI350) -> 0

Sheet TB_PREV
A1: period | B1: County | C1: sub_county | D1: Facility | E1: MFLCode | F1: Support Type | G1: Numerator | H1: Num Tx New Unkown F | I1: Num Tx New <15 F | J1: Num Tx New >15 F | K1: Num Tx New Unkown M | L1: Num Tx New <15 M | M1: Num Tx New 15+ M | N1: Num Already Unkown F | O1: Num Already <15 F | P1: Num Already 15+ F | Q1: Num Already Unkown M | R1: Num Already <15 M | S1: Num Already 15+ M | T1: Num alternative tx new Unkown F | U1: Num alternative tx new <15 F | V1: Num alternative tx new 15+ F | W1: Num alternative tx new Unkown M | X1: Num alternative tx new <15 M | Y1: Num alternative tx new 15+ M | Z1: Num alternative already Unkown F | AA1: Num alternative already <15 F | AB1: Num alternative already 15+ F | AC1: Num alternative already Unkown M | AD1: Num alternative already <15 M | AE1: Num alternative already 15+ M | AF1: Denominator | AG1: Den TX New Unkown F | AH1: Den TX New <15 F | AI1: Den TX New 15+ F | AJ1: Den TX New Unkown M | AK1: Den TX New <15 M | AL1: Den TX New 15+ M | AM1: Den already Unkown F | AN1: Den already <15 F | AO1: Den already 15+ F | AP1: Den already Unkown M | AQ1: Den already <15 M | AR1: Den already 15+ M | AS1: Den alternative tx new Unkown F | AT1: Den alternative tx new <15 F | AU1: Den alternative tx new 15+ F | AV1: Den alternative tx new Unkown M | AW1: Den alternative tx new <15 M | AX1: Den alternative tx new 15+ M | AY1: Den alternative already Unkown F | AZ1: Den alternative alread <15 F | BA1: Den alternative alread 15+ F | BB1: Den alternative alread Unkown M | BC1: Den alternative alread <15 M | BD1: Den alternative alread 15+ M | BE1: ART High Volume | BF1: HTC High Volume | BG1: PMTCT High Volume
A350: =A2 -> 0 | B350: USAID Tujenge Jamii | C350: USAID Tujenge Jamii | D350: USAID Tujenge Jamii | E350: 11111 | F350: DSD | G350: =SUM(G2:G349) -> 0 | H350: =SUM(H2:H349) -> 0 | I350: =SUM(I2:I349) -> 0 | J350: =SUM(J2:J349) -> 0 | K350: =SUM(K2:K349) -> 0 | L350: =SUM(L2:L349) -> 0 | M350: =SUM(M2:M349) -> 0 | N350: =SUM(N2:N349) -> 0 | ... BD350: =SUM(BD2:BD349) -> 0 | BE350: 1 | BF350: 1 | BG350: 1

Sheet GEND_GBV
A1: period | B1: County | C1: sub_county | D1: Facility | E1: MFLCode | F1: Support Type | G1: Numerator | H1: Sexual Violence | I1: Physical and / or Emotional Violence | J1: sv Unkown F | K1: sv <10 F | L1: sv 10-14 F | M1: sv 15-19 F | N1: sv 20-24 F | O1: sv 25-29 F | P1: sv 30-34 F | Q1: sv 35-39 F | R1: sv 40-44 F | S1: sv 45-49 F | T1: sv 50+ F | U1: sv Unkown M | V1: sv <10 M | W1: sv 10-14 M | X1: sv 15-19 M | Y1: sv 20-24 M | Z1: sv 25-29 M | AA1: sv 30-34 M | AB1: sv 35-39 M | AC1: sv 40-44 M | AD1: sv 45-49 M | AE1: sv 50+ M | AF1: pev Unkown F | AG1: pev <10 F | AH1: pev 10-14 F | AI1: pev 15-19 F | AJ1: pev 20-24 F | AK1: pev 25-29 F | AL1: pev 30-34 F | AM1: pev 35-39 F | AN1: pev 40-44 F | AO1: pev 45-49 F | AP1: pev 50+ F | AQ1: pev Unkown M | AR1: pev <10 M | AS1: pev 10-14 M | AT1: pev 15-19 M | AU1: pev 20-24 M | AV1: pev 25-29 M | AW1: pev 30-34 M | AX1: pev 35-39 M | AY1: pev 40-44 M | AZ1: pev 45-49 M | BA1: pev 50+ M | BB1: pep service Unkown F | BC1: pep service <10 F | BD1: pep service 10-14 F | BE1: pep service 15-19 F | BF1: pep service 20-24 F | BG1: pep service 25-29 F | BH1: pep service 30-34 F | BI1: pep service 35-39 F | BJ1: pep service 40-44 F | BK1: pep service 45-49 F | BL1: pep service 50+ F | BM1: pep service Unkown M | BN1: pep service <10 M | BO1: pep service 10-14 M | BP1: pep service 15-19 M | BQ1: pep service 20-24 M | BR1: pep service 25-29 M | BS1: pep service 30-34 M | BT1: pep service 35-39 M | BU1: pep service 40-44 M | BV1: pep service 45-49 M | BW1: pep service 50+ M | BX1: ART High Volume | BY1: HTC High Volume | BZ1: PMTCT High Volume
A350: =A2 -> 0 | B350: USAID Tujenge Jamii | C350: USAID Tujenge Jamii | D350: USAID Tujenge Jamii | E350: 11111 | F350: DSD | G350: =SUM(G2:G349) -> 0 | H350: =SUM(H2:H349) -> 0 | I350: =SUM(I2:I349) -> 0 | J350: =SUM(J2:J349) -> 0 | K350: =SUM(K2:K349) -> 0 | L350: =SUM(L2:L349) -> 0 | M350: =SUM(M2:M349) -> 0 | N350: =SUM(N2:N349) -> 0 | ... BW350: =SUM(BW2:BW349) -> 0 | BX350: 1 | BY350: 1 | BZ350: 1

Sheet Testing Path 2 - HTS TST Mod
B2: Facility Name: | C2: =Prevention!D2 -> USAID Tujenge Jamii | G2: =IFERROR(VLOOKUP(C2,Facilities!F1:H300,2,FALSE),"") | H2: Support Type | K2: =IFERROR(VLOOKUP(C2,Facilities!F1:H300,3,FALSE),"") | M2: Period | N2: ='HTS_TST_Inpatient Services'!A2 -> 0
B4: If MER Results data is unable to be disaggregated by DSD or TA support type, please report ALL data under the TA Support Type
B6: Use Testing Path 2 below to enter HTS_TST results by modalities.
B8: =CONCATENATE(K2,": HTS_TST (Facility)") -> : HTS_TST (Facility)
B9: Auto-Calculate | D9: Number of individuals who received HIV Testing Services (HTS) and received their test results.
B12: Numerator | C12: =IF(SUM(C87,C182,C196,C214,C226,C302,C316,C341,C377,C401,C425,C477,C450,C330)=0,"subtotal",SUM(C87,C182,C196,C214,C226,C302,C316,C341,C377,C401,C425,C477,C450,C330)) -> subtotal
B15: Positive | C15: =IF(SUM(C81,C167:P167,C176:N176,C190:H190,C208:H208,C220,C296,M310,C335,C362:P362,C371:N371,C386:P386,C395:N395,C410:P410,C419:N419,C462:P462,C471:N471,C435:P435,C444:N444,M324)=0,"subtotal",SUM(C81,C167:P167,C176:N176,C190:H190,C208:H208,C220,C296,M310,C335,C362:P362,C371:N371,C386:P386,C395:N395,C410:P410,C419:N419,C462:P462,C471:N471,C435:P435,C444:N444,M324)) -> subtotal
B17: Required | D17: Disaggregated by key population type / Result: Data on key populations should be reported in both the "Disaggregated by key population type" section and the "Disaggregated by Age/Sex/Result" by modality sections.
B19: Category | C19: Positive | D19: Negative | E19: Sub-total
B22: PWID | C22: ='KP_Testing Path 2 - HTS TST Mod'!C22 -> 0 | D22: ='KP_Testing Path 2 - HTS TST Mod'!D22 -> 0 | E22: =IF(SUM(C22:D22)=0,"subtotal",SUM(C22:D22)) -> subtotal
B25: MSM | C25: ='KP_Testing Path 2 - HTS TST Mod'!C25 -> 0 | D25: ='KP_Testing Path 2 - HTS TST Mod'!D25 -> 0 | E25: =IF(SUM(C25:D25)=0,"subtotal",SUM(C25:D25)) -> subtotal
B28: Transgender People | C28: ='KP_Testing Path 2 - HTS TST Mod'!C28 -> 0 | D28: ='KP_Testing Path 2 - HTS TST Mod'!D28 -> 0 | E28: =IF(SUM(C28:D28)=0,"subtotal",SUM(C28:D28)) -> subtotal
B31: FSW | C31: ='KP_Testing Path 2 - HTS TST Mod'!C31 -> 0 | D31: ='KP_Testing Path 2 - HTS TST Mod'!D31 -> 0 | E31: =IF(SUM(C31:D31)=0,"subtotal",SUM(C31:D31)) -> subtotal
B33: People in prison and other closed settings
C34: ='KP_Testing Path 2 - HTS TST Mod'!C34 -> 0 | D34: ='KP_Testing Path 2 - HTS TST Mod'!D34 -> 0 | E34: =IF(SUM(C34:D34)=0,"subtotal",SUM(C34:D34)) -> subtotal
B37: =CONCATENATE('Testing-All Others'!K2,":PMTCT_STAT (Numerator)") -> :PMTCT_STAT (Numerator)
B38: Auto-Calculate | D38: Number of pregnant women with known HIV status at first antenatal care visit (ANC1) (includes those who already knew their HIV status prior to ANC1). Numerator will auto-calculate from the Status and Age Disaggregates.
B41: Numerator | C41: =IF(C59=0,"subtotal",C59) -> subtotal
B43: Required | D43: REQUIRED IF ON PATH 2. Disaggregated by Status and Age
C45: Unknown Age | D45: <10 | E45: 10-14 | F45: 15-19 | G45: 20-24 | H45: 25-29 | I45: 30-34 | J45: 35-39 | K45: 40-44 | L45: 45-49 | M45: 50+
B47: Known Positives | C47: =SUMPRODUCT(('Testing-All Others'!$G$2=PMTCT_STAT!$E$2:$E$350)*(PMTCT_STAT!H$2:H$350)) -> 0 | D47: =SUMPRODUCT(('Testing-All Others'!$G$2=PMTCT_STAT!$E$2:$E$350)*(PMTCT_STAT!I$2:I$350)) -> 0 | E47: =SUMPRODUCT(('Testing-All Others'!$G$2=PMTCT_STAT!$E$2:$E$350)*(PMTCT_STAT!J$2:J$350)) -> 0 | F47: =SUMPRODUCT(('Testing-All Others'!$G$2=PMTCT_STAT!$E$2:$E$350)*(PMTCT_STAT!K$2:K$350)) -> 0 | G47: =SUMPRODUCT(('Testing-All Others'!$G$2=PMTCT_STAT!$E$2:$E$350)*(PMTCT_STAT!L$2:L$350)) -> 0 | H47: =SUMPRODUCT(('Testing-All Others'!$G$2=PMTCT_STAT!$E$2:$E$350)*(PMTCT_STAT!M$2:M$350)) -> 0 | I47: =SUMPRODUCT(('Testing-All Others'!$G$2=PMTCT_STAT!$E$2:$E$350)*(PMTCT_STAT!N$2:N$350)) -> 0 | J47: =SUMPRODUCT(('Testing-All Others'!$G$2=PMTCT_STAT!$E$2:$E$350)*(PMTCT_STAT!O$2:O$350)) -> 0 | ... M47: =SUMPRODUCT(('Testing-All Others'!$G$2=PMTCT_STAT!$E$2:$E$350)*(PMTCT_STAT!R$2:R$350)) -> 0 | N47: =IF(SUM(C47:M47)=0,"subtotal",SUM(C47:M47)) -> subtotal
B50: Newly Tested Positives | C50: =SUMPRODUCT(('Testing-All Others'!$G$2=PMTCT_STAT!$E$2:$E$350)*(PMTCT_STAT!S$2:S$350)) -> 0 | D50: =SUMPRODUCT(('Testing-All Others'!$G$2=PMTCT_STAT!$E$2:$E$350)*(PMTCT_STAT!T$2:T$350)) -> 0 | E50: =SUMPRODUCT(('Testing-All Others'!$G$2=PMTCT_STAT!$E$2:$E$350)*(PMTCT_STAT!U$2:U$350)) -> 0 | F50: =SUMPRODUCT(('Testing-All Others'!$G$2=PMTCT_STAT!$E$2:$E$350)*(PMTCT_STAT!V$2:V$350)) -> 0 | G50: =SUMPRODUCT(('Testing-All Others'!$G$2=PMTCT_STAT!$E$2:$E$350)*(PMTCT_STAT!W$2:W$350)) -> 0 | H50: =SUMPRODUCT(('Testing-All Others'!$G$2=PMTCT_STAT!$E$2:$E$350)*(PMTCT_STAT!X$2:X$350)) -> 0 | I50: =SUMPRODUCT(('Testing-All Others'!$G$2=PMTCT_STAT!$E$2:$E$350)*(PMTCT_STAT!Y$2:Y$350)) -> 0 | J50: =SUMPRODUCT(('Testing-All Others'!$G$2=PMTCT_STAT!$E$2:$E$350)*(PMTCT_STAT!Z$2:Z$350)) -> 0 | ... M50: =SUMPRODUCT(('Testing-All Others'!$G$2=PMTCT_STAT!$E$2:$E$350)*(PMTCT_STAT!AC$2:AC$350)) -> 0 | N50: =IF(SUM(C50:M50)=0,"subtotal",SUM(C50:M50)) -> subtotal
B53: New Negatives | C53: =SUMPRODUCT(('Testing-All Others'!$G$2=PMTCT_STAT!$E$2:$E$350)*(PMTCT_STAT!AD$2:AD$350)) -> 0 | D53: =SUMPRODUCT(('Testing-All Others'!$G$2=PMTCT_STAT!$E$2:$E$350)*(PMTCT_STAT!AE$2:AE$350)) -> 0 | E53: =SUMPRODUCT(('Testing-All Others'!$G$2=PMTCT_STAT!$E$2:$E$350)*(PMTCT_STAT!AF$2:AF$350)) -> 0 | F53: =SUMPRODUCT(('Testing-All Others'!$G$2=PMTCT_STAT!$E$2:$E$350)*(PMTCT_STAT!AG$2:AG$350)) -> 0 | G53: =SUMPRODUCT(('Testing-All Others'!$G$2=PMTCT_STAT!$E$2:$E$350)*(PMTCT_STAT!AH$2:AH$350)) -> 0 | H53: =SUMPRODUCT(('Testing-All Others'!$G$2=PMTCT_STAT!$E$2:$E$350)*(PMTCT_STAT!AI$2:AI$350)) -> 0 | I53: =SUMPRODUCT(('Testing-All Others'!$G$2=PMTCT_STAT!$E$2:$E$350)*(PMTCT_STAT!AJ$2:AJ$350)) -> 0 | J53: =SUMPRODUCT(('Testing-All Others'!$G$2=PMTCT_STAT!$E$2:$E$350)*(PMTCT_STAT!AK$2:AK$350)) -> 0 | ... M53: =SUMPRODUCT(('Testing-All Others'!$G$2=PMTCT_STAT!$E$2:$E$350)*(PMTCT_STAT!AN$2:AN$350)) -> 0 | N53: =IF(SUM(C53:M53)=0,"subtotal",SUM(C53:M53)) -> subtotal
B56: Recent Negatives | C56: =SUMPRODUCT(('Testing-All Others'!$G$2=PMTCT_STAT!$E$2:$E$350)*(PMTCT_STAT!AO$2:AO$350)) -> 0 | D56: =SUMPRODUCT(('Testing-All Others'!$G$2=PMTCT_STAT!$E$2:$E$350)*(PMTCT_STAT!AP$2:AP$350)) -> 0 | E56: =SUMPRODUCT(('Testing-All Others'!$G$2=PMTCT_STAT!$E$2:$E$350)*(PMTCT_STAT!AQ$2:AQ$350)) -> 0 | F56: =SUMPRODUCT(('Testing-All Others'!$G$2=PMTCT_STAT!$E$2:$E$350)*(PMTCT_STAT!AR$2:AR$350)) -> 0 | G56: =SUMPRODUCT(('Testing-All Others'!$G$2=PMTCT_STAT!$E$2:$E$350)*(PMTCT_STAT!AS$2:AS$350)) -> 0 | H56: =SUMPRODUCT(('Testing-All Others'!$G$2=PMTCT_STAT!$E$2:$E$350)*(PMTCT_STAT!AT$2:AT$350)) -> 0 | I56: =SUMPRODUCT(('Testing-All Others'!$G$2=PMTCT_STAT!$E$2:$E$350)*(PMTCT_STAT!AU$2:AU$350)) -> 0 | J56: =SUMPRODUCT(('Testing-All Others'!$G$2=PMTCT_STAT!$E$2:$E$350)*(PMTCT_STAT!AV$2:AV$350)) -> 0 | ... M56: =SUMPRODUCT(('Testing-All Others'!$G$2=PMTCT_STAT!$E$2:$E$350)*(PMTCT_STAT!AY$2:AY$350)) -> 0 | N56: =IF(SUM(C56:M56)=0,"subtotal",SUM(C56:M56)) -> subtotal
B59: Subtotal | C59: =IF(SUM(N47,N50,N53,N56)=0,"subtotal",SUM(N47,N50,N53,N56,)) -> subtotal
B62: =CONCATENATE('Testing-All Others'!K142,":PMTCT_STAT (Denominator)") -> :PMTCT_STAT (Denominator)
B63: Auto-Calculate | D63: Number of new ANC clients in reporting period. Denominator will auto-calculate from the Age Disaggregates.
B66: Denominator | C66: =IF(C75=0,"subtotal",C75) -> subtotal
B68: Required | D68: REQUIRED IF ON PATH 2. Disaggregated by Age (Fine Disaggregate)
C70: Unknown Age | D70: <10 | E70: 10-14 | F70: 15-19 | G70: 20-24 | H70: 25-29 | I70: 30-34 | J70: 35-39 | K70: 40-44 | L70: 45-49 | M70: 50+
C72: =SUMPRODUCT(('Testing-All Others'!$G$2=PMTCT_STAT!$E$2:$E$350)*(PMTCT_STAT!AZ$2:AZ$350)) -> 0 | D72: =SUMPRODUCT(('Testing-All Others'!$G$2=PMTCT_STAT!$E$2:$E$350)*(PMTCT_STAT!BA$2:BA$350)) -> 0 | E72: =SUMPRODUCT(('Testing-All Others'!$G$2=PMTCT_STAT!$E$2:$E$350)*(PMTCT_STAT!BB$2:BB$350)) -> 0 | F72: =SUMPRODUCT(('Testing-All Others'!$G$2=PMTCT_STAT!$E$2:$E$350)*(PMTCT_STAT!BC$2:BC$350)) -> 0 | G72: =SUMPRODUCT(('Testing-All Others'!$G$2=PMTCT_STAT!$E$2:$E$350)*(PMTCT_STAT!BD$2:BD$350)) -> 0 | H72: =SUMPRODUCT(('Testing-All Others'!$G$2=PMTCT_STAT!$E$2:$E$350)*(PMTCT_STAT!BE$2:BE$350)) -> 0 | I72: =SUMPRODUCT(('Testing-All Others'!$G$2=PMTCT_STAT!$E$2:$E$350)*(PMTCT_STAT!BF$2:BF$350)) -> 0 | J72: =SUMPRODUCT(('Testing-All Others'!$G$2=PMTCT_STAT!$E$2:$E$350)*(PMTCT_STAT!BG$2:BG$350)) -> 0 | ... M72: =SUMPRODUCT(('Testing-All Others'!$G$2=PMTCT_STAT!$E$2:$E$350)*(PMTCT_STAT!BJ$2:BJ$350)) -> 0
B75: Subtotal | C75: =IF(SUM(C72:M72)=0,"subtotal",SUM(C72:M72)) -> subtotal
B78: =CONCATENATE(K2,": HTS_TST (Facility) - Index Testing") -> : HTS_TST (Facility) - Index Testing
B79: Auto-Calculate | D79: All Index Case Testing. This data will auto-populate from HTS_INDEX
B81: New Positives | C81: =IF(SUM('Testing Path 2 - HTS TST Mod'!P125,'Testing Path 2 - HTS TST Mod'!P128)=0,"subtotal",SUM('Testing Path 2 - HTS TST Mod'!P125,'Testing Path 2 - HTS TST Mod'!P128)) -> subtotal
B84: New Negatives | C84: =IF(SUM('Testing Path 2 - HTS TST Mod'!P134,'Testing Path 2 - HTS TST Mod'!P137)=0,"subtotal",SUM('Testing Path 2 - HTS TST Mod'!P134,'Testing Path 2 - HTS TST Mod'!P137)) -> subtotal
B87: Sub-Total | C87: =IF(SUM(C81,C84)=0,"subtotal",SUM(C81,C84)) -> subtotal
B89: =CONCATENATE('Testing-All Others'!K2,": HTS_INDEX (Facility)") -> : HTS_INDEX (Facility)
B90: Auto-Calculate | D90: Number of individuals who were identified and tested using index testing services and received their results. Numerator auto-calculates from the sum of the Number of contacts tested by test result and age/sex.
B93: Numerator | C93: =IF(SUM(C141,C122,C131,F151,F154)=0,"subtotal",SUM(C141,C122,C131,F151,F154)) -> subtotal
...

Sheet HTS_TST_Inpatient Services
A1: period | B1: County | C1: sub_county | D1: Facility | E1: MFLCode | F1: Support Type | G1: Pos Unknown Age F | H1: Pos Unknown Age M | I1: Pos < 1 F | J1: Pos < 1 M | K1: Pos 1-4 F | L1: Pos 1-4 M | M1: Pos 5-9 F | N1: Pos 5-9 M | O1: Pos 10-14 F | P1: Pos 10-14 M | Q1: Pos 15-19 F | R1: Pos 15-19 M | S1: Pos 20-24 F | T1: Pos 20-24 M | U1: Neg Unknown Age F | V1: Neg Unknown Age M | W1: Neg < 1 F | X1: Neg < 1 M | Y1: Neg 1-4 F | Z1: Neg 1-4 M | AA1: Neg 5-9 F | AB1: Neg 5-9 M | AC1: Neg 10-14 F | AD1: Neg 10-14 M | AE1: Neg 15-19 F | AF1: Neg 15-19 M | AG1: Neg 20-24 F | AH1: Neg 20-24 M | AI1: Pos 25-29 F | AJ1: Pos 25-29 M | AK1: Pos 30-34 F | AL1: Pos 30-34 M | AM1: Pos 35-39 F | AN1: Pos 35-39 M | AO1: Pos 40-44 F | AP1: Pos 40-44 M | AQ1: Pos 45-49 F | AR1: Pos 45-49 M | AS1: Pos 50 F | AT1: Pos 50 M | AU1: Neg 25-29 F | AV1: Neg 25-29 M | AW1: Neg 30-34 F | AX1: Neg 30-34 M | AY1: Neg 35-39 F | AZ1: Neg 35-39 M | BA1: Neg 40-44 F | BB1: Neg 40-44 M | BC1: Neg 45-49 F | BD1: Neg 45-49 M | BE1: Neg 50 F | BF1: Neg 50 M | BG1: Inpatient Total | BH1: ART High Volume | BI1: HTC High Volume | BJ1: PMTCT High Volume
A350: =A2 -> 0 | B350: USAID Tujenge Jamii | C350: USAID Tujenge Jamii | D350: USAID Tujenge Jamii | E350: 11111 | F350: DSD | G350: =SUM(G2:G349) -> 0 | H350: =SUM(H2:H349) -> 0 | I350: =SUM(I2:I349) -> 0 | J350: =SUM(J2:J349) -> 0 | K350: =SUM(K2:K349) -> 0 | L350: =SUM(L2:L349) -> 0 | M350: =SUM(M2:M349) -> 0 | N350: =SUM(N2:N349) -> 0 | ... BG350: =SUM(BG2:BG349) -> 0 | BH350: 1 | BI350: 1 | BJ350: 1

Sheet HTS_TST_Pediatric Services
A1: period | B1: County | C1: sub_county | D1: Facility | E1: MFLCode | F1: Support Type | G1: Pos Uknkown Age F | H1: Pos Uknkown Age M | I1: Pos < 1 F | J1: Pos < 1 M | K1: Pos 1-4 F | L1: Pos 1-4 M | M1: Neg Uknown Age F | N1: Neg Uknkown Age M | O1: Neg < 1 F | P1: Neg < 1 M | Q1: Neg 1-4 F | R1: Neg 1-4 M | S1: Ped Total | T1: ART High Volume | U1: HTC High Volume | V1: PMTCT High Volume
A350: =A2 -> 0 | B350: USAID Tujenge Jamii | C350: USAID Tujenge Jamii | D350: USAID Tujenge Jamii | E350: 11111 | F350: DSD | G350: =SUM(G2:G349) -> 0 | H350: =SUM(H2:H349) -> 0 | I350: =SUM(I2:I349) -> 0 | J350: =SUM(J2:J349) -> 0 | K350: =SUM(K2:K349) -> 0 | L350: =SUM(L2:L349) -> 0 | M350: =SUM(M2:M349) -> 0 | N350: =SUM(N2:N349) -> 0 | ... S350: =SUM(S2:S349) -> 0 | T350: 1 | U350: 1 | V350: 1

Sheet HTS_TST_Malnutrition Clinics
A1: period | B1: County | C1: sub_county | D1: Facility | E1: MFLCode | F1: Support Type | G1: Pos Uknkown Age F | H1: Pos Uknkown Age M | I1: Pos < 1 F | J1: Pos < 1 M | K1: Pos 1-4 F | L1: Pos 1-4 M | M1: Neg Uknkown Age F | N1: Neg Uknkown Age M | O1: Neg < 1 F | P1: Neg < 1 M | Q1: Neg 1-4 F | R1: Neg 1-4 M | S1: Mal Total | T1: ART High Volume | U1: HTC High Volume | V1: PMTCT High Volume
A350: =A2 -> 0 | B350: USAID Tujenge Jamii | C350: USAID Tujenge Jamii | D350: USAID Tujenge Jamii | E350: 11111 | F350: DSD | G350: =SUM(G2:G349) -> 0 | H350: =SUM(H2:H349) -> 0 | I350: =SUM(I2:I349) -> 0 | J350: =SUM(J2:J349) -> 0 | K350: =SUM(K2:K349) -> 0 | L350: =SUM(L2:L349) -> 0 | M350: =SUM(M2:M349) -> 0 | N350: =SUM(N2:N349) -> 0 | ... S350: =SUM(S2:S349) -> 0

Sheet HTS_TST_PMTCT Post ANC1_Preg_LD
A1: period | B1: County | C1: sub_county | D1: Facility | E1: MFLCode | F1: Support Type | G1: Pos Unknown Age | H1: Pos 10-14 | I1: Pos 15-19 | J1: Pos 20-24 | K1: Pos 25-29 | L1: Pos 30-34 | M1: Pos 35-39 | N1: Pos 40-44 | O1: Pos 45-49 | P1: Pos 50+ | Q1: Neg Unknown Age | R1: Neg 10-14 | S1: Neg 15-19 | T1: Neg 20-24 | U1: Neg 25-29 | V1: Neg 30-34 | W1: Neg 35-39 | X1: Neg 40-44 | Y1: Neg 45-49 | Z1: Neg 50+ | AA1: PMTCT PNC Total | AB1: ART High Volume | AC1: HTC High Volume | AD1: PMTCT High Volume
A350: =A2 -> 0 | B350: USAID Tujenge Jamii | C350: USAID Tujenge Jamii | D350: USAID Tujenge Jamii | E350: 11111 | F350: DSD | G350: =SUM(G2:G349) -> 0 | H350: =SUM(H2:H349) -> 0 | I350: =SUM(I2:I349) -> 0 | J350: =SUM(J2:J349) -> 0 | K350: =SUM(K2:K349) -> 0 | L350: =SUM(L2:L349) -> 0 | M350: =SUM(M2:M349) -> 0 | N350: =SUM(N2:N349) -> 0 | ... AA350: =SUM(AA2:AA349) -> 0 | AB350: 1 | AC350: 1 | AD350: 1

Sheet HTS_TST_PMTCT Post ANC1_BF
A1: period | B1: County | C1: sub_county | D1: Facility | E1: MFLCode | F1: Support Type | G1: Pos Unknown Age | H1: Pos 10-14 | I1: Pos 15-19 | J1: Pos 20-24 | K1: Pos 25-29 | L1: Pos 30-34 | M1: Pos 35-39 | N1: Pos 40-44 | O1: Pos 45-49 | P1: Pos 50+ | Q1: Neg Unknown Age | R1: Neg 10-14 | S1: Neg 15-19 | T1: Neg 20-24 | U1: Neg 25-29 | V1: Neg 30-34 | W1: Neg 35-39 | X1: Neg 40-44 | Y1: Neg 45-49 | Z1: Neg 50+ | AA1: PMTCT PNC Total | AB1: ART High Volume | AC1: HTC High Volume | AD1: PMTCT High Volume
A350: =A2 -> 0 | B350: USAID Tujenge Jamii | C350: USAID Tujenge Jamii | D350: USAID Tujenge Jamii | E350: 11111 | F350: DSD | G350: =SUM(G2:G349) -> 0 | H350: =SUM(H2:H349) -> 0 | I350: =SUM(I2:I349) -> 0 | J350: =SUM(J2:J349) -> 0 | K350: =SUM(K2:K349) -> 0 | L350: =SUM(L2:L349) -> 0 | M350: =SUM(M2:M349) -> 0 | N350: =SUM(N2:N349) -> 0 | ... AA350: =SUM(AA2:AA349) -> 0 | AB350: 1 | AC350: 1 | AD350: 1

Sheet HTS_TST_STI Clinic
A1: period | B1: County | C1: sub_county | D1: Facility | E1: MFLCode | F1: Support Type | G1: Pos Unknown Age F | H1: Pos Unknown Age M | I1: Pos < 1 F | J1: Pos < 1 M | K1: Pos 1-4 F | L1: Pos 1-4 M | M1: Pos 5-9 F | N1: Pos 5-9 M | O1: Pos 10-14 F | P1: Pos 10-14 M | Q1: Pos 15-19 F | R1: Pos 15-19 M | S1: Pos 20-24 F | T1: Pos 20-24 M | U1: Neg Unknown Age F | V1: Neg Unknown Age M | W1: Neg < 1 F | X1: Neg < 1 M | Y1: Neg 1-4 F | Z1: Neg 1-4 M | AA1: Neg 5-9 F | AB1: Neg 5-9 M | AC1: Neg 10-14 F | AD1: Neg 10-14 M | AE1: Neg 15-19 F | AF1: Neg 15-19 M | AG1: Neg 20-24 F | AH1: Neg 20-24 M | AI1: Pos 25-29 F | AJ1: Pos 25-29 M | AK1: Pos 30-34 F | AL1: Pos 30-34 M | AM1: Pos 35-39 F | AN1: Pos 35-39 M | AO1: Pos 40-44 F | AP1: Pos 40-44 M | AQ1: Pos 45-49 F | AR1: Pos 45-49 M | AS1: Pos 50 F | AT1: Pos 50 M | AU1: Neg 25-29 F | AV1: Neg 25-29 M | AW1: Neg 30-34 F | AX1: Neg 30-34 M | AY1: Neg 35-39 F | AZ1: Neg 35-39 M | BA1: Neg 40-44 F | BB1: Neg 40-44 M | BC1: Neg 45-49 F | BD1: Neg 45-49 M | BE1: Neg 50 F | BF1: Neg 50 M | BG1: STI Total | BH1: ART High Volume | BI1: HTC High Volume | BJ1: PMTCT High Volume
A350: =A2 -> 0 | B350: USAID Tujenge Jamii | C350: USAID Tujenge Jamii | D350: USAID Tujenge Jamii | E350: 11111 | F350: DSD | G350: =SUM(G2:G349) -> 0 | H350: =SUM(H2:H349) -> 0 | I350: =SUM(I2:I349) -> 0 | J350: =SUM(J2:J349) -> 0 | K350: =SUM(K2:K349) -> 0 | L350: =SUM(L2:L349) -> 0 | M350: =SUM(M2:M349) -> 0 | N350: =SUM(N2:N349) -> 0 | ... BG350: =SUM(BG2:BG349) -> 0 | BH350: 1 | BI350: 1 | BJ350: 1

Sheet HTS_TST_Emergency Ward
A1: period | B1: County | C1: sub_county | D1: Facility | E1: MFLCode | F1: Support Type | G1: Pos Unknown Age F | H1: Pos Unknown Age M | I1: Pos < 1 F | J1: Pos < 1 M | K1: Pos 1-4 F | L1: Pos 1-4 M | M1: Pos 5-9 F | N1: Pos 5-9 M | O1: Pos 10-14 F | P1: Pos 10-14 M | Q1: Pos 15-19 F | R1: Pos 15-19 M | S1: Pos 20-24 F | T1: Pos 20-24 M | U1: Neg Unknown Age F | V1: Neg Unknown Age M | W1: Neg < 1 F | X1: Neg < 1 M | Y1: Neg 1-4 F | Z1: Neg 1-4 M | AA1: Neg 5-9 F | AB1: Neg 5-9 M | AC1: Neg 10-14 F | AD1: Neg 10-14 M | AE1: Neg 15-19 F | AF1: Neg 15-19 M | AG1: Neg 20-24 F | AH1: Neg 20-24 M | AI1: Pos 25-29 F | AJ1: Pos 25-29 M | AK1: Pos 30-34 F | AL1: Pos 30-34 M | AM1: Pos 35-39 F | AN1: Pos 35-39 M | AO1: Pos 40-44 F | AP1: Pos 40-44 M | AQ1: Pos 45-49 F | AR1: Pos 45-49 M | AS1: Pos 50 F | AT1: Pos 50 M | AU1: Neg 25-29 F | AV1: Neg 25-29 M | AW1: Neg 30-34 F | AX1: Neg 30-34 M | AY1: Neg 35-39 F | AZ1: Neg 35-39 M | BA1: Neg 40-44 F | BB1: Neg 40-44 M | BC1: Neg 45-49 F | BD1: Neg 45-49 M | BE1: Neg 50 F | BF1: Neg 50 M | BG1: Emergency Total | BH1: ART High Volume | BI1: HTC High Volume | BJ1: PMTCT High Volume
A350: =A2 -> 0 | B350: USAID Tujenge Jamii | C350: USAID Tujenge Jamii | D350: USAID Tujenge Jamii | E350: 11111 | F350: DSD | G350: =SUM(G2:G349) -> 0 | H350: =SUM(H2:H349) -> 0 | I350: =SUM(I2:I349) -> 0 | J350: =SUM(J2:J349) -> 0 | K350: =SUM(K2:K349) -> 0 | L350: =SUM(L2:L349) -> 0 | M350: =SUM(M2:M349) -> 0 | N350: =SUM(N2:N349) -> 0 | ... BG350: =SUM(BG2:BG349) -> 0

Sheet HTS_TST_Other PITC
A1: period | B1: County | C1: sub_county | D1: Facility | E1: MFLCode | F1: Support Type | G1: Pos Unknown Age F | H1: Pos Unknown Age M | I1: Pos < 1 F | J1: Pos < 1 M | K1: Pos 1-4 F | L1: Pos 1-4 M | M1: Pos 5-9 F | N1: Pos 5-9 M | O1: Pos 10-14 F | P1: Pos 10-14 M | Q1: Pos 15-19 F | R1: Pos 15-19 M | S1: Pos 20-24 F | T1: Pos 20-24 M | U1: Neg Unknown Age F | V1: Neg Unknown Age M | W1: Neg < 1 F | X1: Neg < 1 M | Y1: Neg 1-4 F | Z1: Neg 1-4 M | AA1: Neg 5-9 F | AB1: Neg 5-9 M | AC1: Neg 10-14 F | AD1: Neg 10-14 M | AE1: Neg 15-19 F | AF1: Neg 15-19 M | AG1: Neg 20-24 F | AH1: Neg 20-24 M | AI1: Pos 25-29 F | AJ1: Pos 25-29 M | AK1: Pos 30-34 F | AL1: Pos 30-34 M | AM1: Pos 35-39 F | AN1: Pos 35-39 M | AO1: Pos 40-44 F | AP1: Pos 40-44 M | AQ1: Pos 45-49 F | AR1: Pos 45-49 M | AS1: Pos 50 F | AT1: Pos 50 M | AU1: Neg 25-29 F | AV1: Neg 25-29 M | AW1: Neg 30-34 F | AX1: Neg 30-34 M | AY1: Neg 35-39 F | AZ1: Neg 35-39 M | BA1: Neg 40-44 F | BB1: Neg 40-44 M | BC1: Neg 45-49 F | BD1: Neg 45-49 M | BE1: Neg 50 F | BF1: Neg 50 M | BG1: Total Other PITC | BH1: ART High Volume | BI1: HTC High Volume | BJ1: PMTCT High Volume
A350: =A2 -> 0 | B350: USAID Tujenge Jamii | C350: USAID Tujenge Jamii | D350: USAID Tujenge Jamii | E350: 11111 | F350: DSD | G350: =SUM(G2:G349) -> 0 | H350: =SUM(H2:H349) -> 0 | I350: =SUM(I2:I349) -> 0 | J350: =SUM(J2:J349) -> 0 | K350: =SUM(K2:K349) -> 0 | L350: =SUM(L2:L349) -> 0 | M350: =SUM(M2:M349) -> 0 | N350: =SUM(N2:N349) -> 0 | ... BG350: =SUM(BG2:BG349) -> 0 | BH350: 1 | BI350: 1 | BJ350: 1

Sheet HTS_TST_VCT
A1: period | B1: County | C1: sub_county | D1: Facility | E1: MFLCode | F1: Support Type | G1: Pos Unknown Age F | H1: Pos Unknown Age M | I1: Pos < 1 F | J1: Pos < 1 M | K1: Pos 1-4 F | L1: Pos 1-4 M | M1: Pos 5-9 F | N1: Pos 5-9 M | O1: Pos 10-14 F | P1: Pos 10-14 M | Q1: Pos 15-19 F | R1: Pos 15-19 M | S1: Pos 20-24 F | T1: Pos 20-24 M | U1: Neg Unknown Age F | V1: Neg Unknown Age M | W1: Neg < 1 F | X1: Neg < 1 M | Y1: Neg 1-4 F | Z1: Neg 1-4 M | AA1: Neg 5-9 F | AB1: Neg 5-9 M | AC1: Neg 10-14 F | AD1: Neg 10-14 M | AE1: Neg 15-19 F | AF1: Neg 15-19 M | AG1: Neg 20-24 F | AH1: Neg 20-24 M | AI1: Pos 25-29 F | AJ1: Pos 25-29 M | AK1: Pos 30-34 F | AL1: Pos 30-34 M | AM1: Pos 35-39 F | AN1: Pos 35-39 M | AO1: Pos 40-44 F | AP1: Pos 40-44 M | AQ1: Pos 45-49 F | AR1: Pos 45-49 M | AS1: Pos 50 F | AT1: Pos 50 M | AU1: Neg 25-29 F | AV1: Neg 25-29 M | AW1: Neg 30-34 F | AX1: Neg 30-34 M | AY1: Neg 35-39 F | AZ1: Neg 35-39 M | BA1: Neg 40-44 F | BB1: Neg 40-44 M | BC1: Neg 45-49 F | BD1: Neg 45-49 M | BE1: Neg 50 F | BF1: Neg 50 M | BG1: VCT Total | BH1: ART High Volume | BI1: HTC High Volume | BJ1: PMTCT High Volume
A350: =A2 -> 0 | B350: USAID Tujenge Jamii | C350: USAID Tujenge Jamii | D350: USAID Tujenge Jamii | E350: 11111 | F350: DSD | G350: =SUM(G2:G349) -> 0 | H350: =SUM(H2:H349) -> 0 | I350: =SUM(I2:I349) -> 0 | J350: =SUM(J2:J349) -> 0 | K350: =SUM(K2:K349) -> 0 | L350: =SUM(L2:L349) -> 0 | M350: =SUM(M2:M349) -> 0 | N350: =SUM(N2:N349) -> 0 | ... BG350: =SUM(BG2:BG349) -> 0 | BH350: 1 | BI350: 1 | BJ350: 1

Sheet HTS_TST_SNS
A1: period | B1: County | C1: sub_county | D1: Facility | E1: MFLCode | F1: Support Type | G1: Pos Unknown Age F | H1: Pos Unknown Age M | I1: Pos < 1 F | J1: Pos < 1 M | K1: Pos 1-4 F | L1: Pos 1-4 M | M1: Pos 5-9 F | N1: Pos 5-9 M | O1: Pos 10-14 F | P1: Pos 10-14 M | Q1: Pos 15-19 F | R1: Pos 15-19 M | S1: Pos 20-24 F | T1: Pos 20-24 M | U1: Neg Unknown Age F | V1: Neg Unknown Age M | W1: Neg < 1 F | X1: Neg < 1 M | Y1: Neg 1-4 F | Z1: Neg 1-4 M | AA1: Neg 5-9 F | AB1: Neg 5-9 M | AC1: Neg 10-14 F | AD1: Neg 10-14 M | AE1: Neg 15-19 F | AF1: Neg 15-19 M | AG1: Neg 20-24 F | AH1: Neg 20-24 M | AI1: Pos 25-29 F | AJ1: Pos 25-29 M | AK1: Pos 30-34 F | AL1: Pos 30-34 M | AM1: Pos 35-39 F | AN1: Pos 35-39 M | AO1: Pos 40-44 F | AP1: Pos 40-44 M | AQ1: Pos 45-49 F | AR1: Pos 45-49 M | AS1: Pos 50 F | AT1: Pos 50 M | AU1: Neg 25-29 F | AV1: Neg 25-29 M | AW1: Neg 30-34 F | AX1: Neg 30-34 M | AY1: Neg 35-39 F | AZ1: Neg 35-39 M | BA1: Neg 40-44 F | BB1: Neg 40-44 M | BC1: Neg 45-49 F | BD1: Neg 45-49 M | BE1: Neg 50 F | BF1: Neg 50 M | BG1: Total SNS | BH1: ART High Volume | BI1: HTC High Volume | BJ1: PMTCT High Volume
A350: =A2 -> 0 | B350: USAID Tujenge Jamii | C350: USAID Tujenge Jamii | D350: USAID Tujenge Jamii | E350: 11111 | F350: DSD | G350: =SUM(G2:G349) -> 0 | H350: =SUM(H2:H349) -> 0 | I350: =SUM(I2:I349) -> 0 | J350: =SUM(J2:J349) -> 0 | K350: =SUM(K2:K349) -> 0 | L350: =SUM(L2:L349) -> 0 | M350: =SUM(M2:M349) -> 0 | N350: =SUM(N2:N349) -> 0 | ... BG350: =SUM(BG2:BG349) -> 0 | BH350: 1 | BI350: 1 | BJ350: 1

Sheet Testing-All Others
B2: Facility Name: | C2: =Prevention!D2 -> USAID Tujenge Jamii | G2: =IFERROR(VLOOKUP(C2,Facilities!F1:H300,2,FALSE),"") | H2: Support Type | K2: =IFERROR(VLOOKUP(C2,Facilities!F1:H300,3,FALSE),"") | M2: Period | N2: =HTS_INDEX!A2 -> 0
B74: Facility Name: | C74: =C2 -> USAID Tujenge Jamii | H74: Support Type | K74: =K2 | M74: Period | N74: =N2 -> 0
B76: If MER Results data is unable to be disaggregated by DSD or TA support type, please report ALL data under the TA Support Type
B78: =CONCATENATE(K2,": HTS_SELF") -> : HTS_SELF
B79: Auto-Calculate | D79: Number of individual HIV self-test kits distributed. Numerator will auto-calculate from the directly-assisted/unassisted self-testing types. HTS_SELF is not reported under HTS_TST (or HTS_TST_POS) results.
B82: Sub-Total | C82: =IF(SUM(C90:L90,C93:L93,C103:L103,C106:L106,C109)=0,"subtotal",SUM(C90:L90,C93:L93,C103:L103,C106:L106,C109)) -> subtotal
B85: Auto-Calculate | D85: Enter the number of self-test kits distributed for directly assisted testing. Disaggregated by Directly Assisted / Age / Sex
C88: Unknown Age | D88: 10-14 | E88: 15-19 | F88: 20-24 | G88: 25-29 | H88: 30-34 | I88: 35-39 | J88: 40-44 | K88: 45-49 | L88: 50+
B90: Female | C90: =SUMPRODUCT(($G$2=HTS_SELF!$E$2:$E$350)*(HTS_SELF!H$2:H$350)) -> 0 | D90: =SUMPRODUCT(($G$2=HTS_SELF!$E$2:$E$350)*(HTS_SELF!I$2:I$350)) -> 0 | E90: =SUMPRODUCT(($G$2=HTS_SELF!$E$2:$E$350)*(HTS_SELF!J$2:J$350)) -> 0 | F90: =SUMPRODUCT(($G$2=HTS_SELF!$E$2:$E$350)*(HTS_SELF!K$2:K$350)) -> 0 | G90: =SUMPRODUCT(($G$2=HTS_SELF!$E$2:$E$350)*(HTS_SELF!L$2:L$350)) -> 0 | H90: =SUMPRODUCT(($G$2=HTS_SELF!$E$2:$E$350)*(HTS_SELF!M$2:M$350)) -> 0 | I90: =SUMPRODUCT(($G$2=HTS_SELF!$E$2:$E$350)*(HTS_SELF!N$2:N$350)) -> 0 | J90: =SUMPRODUCT(($G$2=HTS_SELF!$E$2:$E$350)*(HTS_SELF!O$2:O$350)) -> 0 | ... L90: =SUMPRODUCT(($G$2=HTS_SELF!$E$2:$E$350)*(HTS_SELF!Q$2:Q$350)) -> 0 | M90: =IF(SUM(C90:L90)=0,"subtotal",SUM(C90:L90)) -> subtotal
B93: Male | C93: =SUMPRODUCT(($G$2=HTS_SELF!$E$2:$E$350)*(HTS_SELF!R$2:R$350)) -> 0 | D93: =SUMPRODUCT(($G$2=HTS_SELF!$E$2:$E$350)*(HTS_SELF!S$2:S$350)) -> 0 | E93: =SUMPRODUCT(($G$2=HTS_SELF!$E$2:$E$350)*(HTS_SELF!T$2:T$350)) -> 0 | F93: =SUMPRODUCT(($G$2=HTS_SELF!$E$2:$E$350)*(HTS_SELF!U$2:U$350)) -> 0 | G93: =SUMPRODUCT(($G$2=HTS_SELF!$E$2:$E$350)*(HTS_SELF!V$2:V$350)) -> 0 | H93: =SUMPRODUCT(($G$2=HTS_SELF!$E$2:$E$350)*(HTS_SELF!W$2:W$350)) -> 0 | I93: =SUMPRODUCT(($G$2=HTS_SELF!$E$2:$E$350)*(HTS_SELF!X$2:X$350)) -> 0 | J93: =SUMPRODUCT(($G$2=HTS_SELF!$E$2:$E$350)*(HTS_SELF!Y$2:Y$350)) -> 0 | ... L93: =SUMPRODUCT(($G$2=HTS_SELF!$E$2:$E$350)*(HTS_SELF!AA$2:AA$350)) -> 0 | M93: =IF(SUM(C93:L93)=0,"subtotal",SUM(C93:L93)) -> subtotal
B96: Sub-Total | C96: =IF(SUM(C90:L90,C93:L93)=0,"subtotal",SUM(C90:L90,C93:L93)) -> subtotal
B98: Auto-Calculate | D98: Enter the number of self-test kits distributed for unassisted testing. Disaggregated by Unassisted /Age/ Sex.
C101: Unknown Age | D101: 10-14 | E101: 15-19 | F101: 20-24 | G101: 25-29 | H101: 30-34 | I101: 35-39 | J101: 40-44 | K101: 45-49 | L101: 50+
B103: Female | C103: =SUMPRODUCT(($G$2=HTS_SELF!$E$2:$E$350)*(HTS_SELF!AB$2:AB$350)) -> 0 | D103: =SUMPRODUCT(($G$2=HTS_SELF!$E$2:$E$350)*(HTS_SELF!AC$2:AC$350)) -> 0 | E103: =SUMPRODUCT(($G$2=HTS_SELF!$E$2:$E$350)*(HTS_SELF!AD$2:AD$350)) -> 0 | F103: =SUMPRODUCT(($G$2=HTS_SELF!$E$2:$E$350)*(HTS_SELF!AE$2:AE$350)) -> 0 | G103: =SUMPRODUCT(($G$2=HTS_SELF!$E$2:$E$350)*(HTS_SELF!AF$2:AF$350)) -> 0 | H103: =SUMPRODUCT(($G$2=HTS_SELF!$E$2:$E$350)*(HTS_SELF!AG$2:AG$350)) -> 0 | I103: =SUMPRODUCT(($G$2=HTS_SELF!$E$2:$E$350)*(HTS_SELF!AH$2:AH$350)) -> 0 | J103: =SUMPRODUCT(($G$2=HTS_SELF!$E$2:$E$350)*(HTS_SELF!AI$2:AI$350)) -> 0 | ... L103: =SUMPRODUCT(($G$2=HTS_SELF!$E$2:$E$350)*(HTS_SELF!AK$2:AK$350)) -> 0 | M103: =IF(SUM(C103:L103)=0,"subtotal",SUM(C103:L103)) -> subtotal
B106: Male | C106: =SUMPRODUCT(($G$2=HTS_SELF!$E$2:$E$350)*(HTS_SELF!AL$2:AL$350)) -> 0 | D106: =SUMPRODUCT(($G$2=HTS_SELF!$E$2:$E$350)*(HTS_SELF!AM$2:AM$350)) -> 0 | E106: =SUMPRODUCT(($G$2=HTS_SELF!$E$2:$E$350)*(HTS_SELF!AN$2:AN$350)) -> 0 | F106: =SUMPRODUCT(($G$2=HTS_SELF!$E$2:$E$350)*(HTS_SELF!AO$2:AO$350)) -> 0 | G106: =SUMPRODUCT(($G$2=HTS_SELF!$E$2:$E$350)*(HTS_SELF!AP$2:AP$350)) -> 0 | H106: =SUMPRODUCT(($G$2=HTS_SELF!$E$2:$E$350)*(HTS_SELF!AQ$2:AQ$350)) -> 0 | I106: =SUMPRODUCT(($G$2=HTS_SELF!$E$2:$E$350)*(HTS_SELF!AR$2:AR$350)) -> 0 | J106: =SUMPRODUCT(($G$2=HTS_SELF!$E$2:$E$350)*(HTS_SELF!AS$2:AS$350)) -> 0 | ... L106: =SUMPRODUCT(($G$2=HTS_SELF!$E$2:$E$350)*(HTS_SELF!AU$2:AU$350)) -> 0 | M106: =IF(SUM(C106:L106)=0,"subtotal",SUM(C106:L106)) -> subtotal
B109: Unknown Sex | C109: =SUMPRODUCT(($G$2=HTS_SELF!$E$2:$E$350)*(HTS_SELF!AV$2:AV$350)) -> 0
B112: Sub-Total | C112: =IF(SUM(C106:L106,C103:L103)=0,"subtotal",SUM(C106:L106,C103:L103)) -> subtotal
B114: Required | D114: Enter the number of self-test kits distributed to key populations for directly assisted or unassisted testing. Disaggregated by key population type / self-testing type: Data on key populations should be reported in both the "Disaggregated by key population type/self-testing type" section and the "Disaggregated by Directly Assisted/Age/Sex" & "Disaggregated by Unassisted/Age/Sex" sections.
B116: Category | C116: Positive | D116: Negative | E116: Sub-total
B119: PWID | C119: 0 | D119: 0 | E119: =IF(SUM(C119:D119)=0,"subtotal",SUM(C119:D119)) -> subtotal
B122: MSM | C122: 0 | D122: 0 | E122: =IF(SUM(C122:D122)=0,"subtotal",SUM(C122:D122)) -> subtotal
B125: Transgender People | C125: 0 | D125: 0 | E125: =IF(SUM(C125:D125)=0,"subtotal",SUM(C125:D125)) -> subtotal
B128: FSW | C128: 0 | D128: 0 | E128: =IF(SUM(C128:D128)=0,"subtotal",SUM(C128:D128)) -> subtotal
B130: People in prison and other closed settings
C131: 0 | D131: 0 | E131: =IF(SUM(C131:D131)=0,"subtotal",SUM(C131:D131)) -> subtotal
B133: Required | D133: Disaggregate of Unassisted self-testing kits distributed. Enter the number of unassisted self-test kits distributed for use by:
C135: Self | E135: Sex Partner | G135: Caregiver For the Child | I135: Other
B138: Unassisted self-testing kit used by: | C138: =SUMPRODUCT(($G$2=HTS_SELF!$E$2:$E$350)*(HTS_SELF!AW$2:AW$350)) -> 0 | E138: =SUMPRODUCT(($G$2=HTS_SELF!$E$2:$E$350)*(HTS_SELF!AX$2:AX$350)) -> 0 | G138: =SUMPRODUCT(($G$2=HTS_SELF!$E$2:$E$350)*(HTS_SELF!AY$2:AY$350)) -> 0 | I138: =SUMPRODUCT(($G$2=HTS_SELF!$E$2:$E$350)*(HTS_SELF!AZ$2:AZ$350)) -> 0
B142: Facility Name: | C142: =C2 -> USAID Tujenge Jamii | H142: Support Type | K142: =K2 | M142: Period | N142: =N2 -> 0
B184: =CONCATENATE(K142,":PMTCT_EID") -> :PMTCT_EID
B185: Auto-Calculate | D185: Number of HIV-exposed infants who had a virologic HIV test (sample collected) by 12 months of birth during the reporting period. Numerator will auto-calculate from infant age at first test.
B188: Numerator | C188: =IF(SUM(F194,H194,F197,H197)=0,"subtotal",SUM(F194,H194,F197,H197)) -> subtotal
B190: Required | D190: Disaggregated by infant age at first test
F192: 0 ≤ 2 Months | H192: 2-12 Months
B193: First Test
F194: =SUMPRODUCT(($G$2=PMTCT_EID!$E$2:$E$350)*(PMTCT_EID!G$2:G$350)) -> 0 | H194: =SUMPRODUCT(($G$2=PMTCT_EID!$E$2:$E$350)*(PMTCT_EID!H$2:H$350)) -> 0
B196: Second Test or more
F197: =SUMPRODUCT(($G$2=PMTCT_EID!$E$2:$E$350)*(PMTCT_EID!I$2:I$350)) -> 0 | H197: =SUMPRODUCT(($G$2=PMTCT_EID!$E$2:$E$350)*(PMTCT_EID!J$2:J$350)) -> 0
B200: =CONCATENATE(K142,":PMTCT_HEI") -> :PMTCT_HEI
B201: Auto-Calculate | D201: Number of HIV-infected infants identified in the reporting period, whose diagnostic sample was collected by 12 months of age.Numerator will auto-calculate from the HIV-infected infant age disaggregation.
...

Sheet HTS_INDEX
A1: period | B1: County | C1: sub_county | D1: Facility | E1: MFLCode | F1: Support Type | G1: Index Offered Unknown Age F | H1: Index Offered < 1 F | I1: Index Offered 1-4 F | J1: Index Offered 5-9 F | K1: Index Offered 10-14 F | L1: Index Offered 15-19 F | M1: Index Offered 20-24 F | N1: Index Offered 25-29 F | O1: Index Offered 30-34 F | P1: Index Offered 35-39 F | Q1: Index Offered 40-44 F | R1: Index Offered 45-49 F | S1: Index Offered 50+ F | T1: Index Offered Unknown Age M | U1: Index Offered < 1 M | V1: Index Offered 1-4 M | W1: Index Offered 5-9 M | X1: Index Offered 10-14 M | Y1: Index Offered 15-19 M | Z1: Index Offered 20-24 M | AA1: Index Offered 25-29 M | AB1: Index Offered 30-34 M | AC1: Index Offered 35-39 M | AD1: Index Offered 40-44 M | AE1: Index Offered 45-49 M | AF1: Index Offered 50+ M | AG1: Index Accepted Unknown Age F | AH1: Index Accepted < 1 F | AI1: Index Accepted 1-4 F | AJ1: Index Accepted 5-9 F | AK1: Index Accepted 10-14 F | AL1: Index Accepted 15-19 F | AM1: Index Accepted 20-24 F | AN1: Index Accepted 25-29 F | AO1: Index Accepted 30-34 F | AP1: Index Accepted 35-39 F | AQ1: Index Accepted 40-44 F | AR1: Index Accepted 45-49 F | AS1: Index Accepted 50+ F | AT1: Index Accepted Unknown Age M | AU1: Index Accepted < 1 M | AV1: Index Accepted 1-4 M | AW1: Index Accepted 5-9 M | AX1: Index Accepted 10-14 M | AY1: Index Accepted 15-19 M | AZ1: Index Accepted 20-24 M | BA1: Index Accepted 25-29 M | BB1: Index Accepted 30-34 M | BC1: Index Accepted 35-39 M | BD1: Index Accepted 40-44 M | BE1: Index Accepted 45-49 M | BF1: Index Accepted 50+ M | BG1: Contacts Elicited Unknown Age F | BH1: Contacts Elicited < 15 F | BI1: Contacts Elicited 15+ F | BJ1: Contacts Elicited Unknown Age M | BK1: Contacts Elicited < 15 M | BL1: Contacts Elicited 15+ M | BM1: KP Unknown Age F | BN1: KP < 1 F | BO1: KP 1-4 F | BP1: KP 5-9 F | BQ1: KP 10-14 F | BR1: KP 15-19 F | BS1: KP 20-24 F | BT1: KP 25-29 F | BU1: KP 30-34 F | BV1: KP 35-39 F | BW1: KP 40-44 F | BX1: KP 45-49 F | BY1: KP 50+ F | BZ1: KP Unknown Age M | CA1: KP < 1 M | CB1: KP 1-4 M | CC1: KP 5-9 M | CD1: KP 10-14 M | CE1: KP 15-19 M | CF1: KP 20-24 M | CG1: KP 25-29 M | CH1: KP 30-34 M | CI1: KP 35-39 M | CJ1: KP 40-44 M | CK1: KP 45-49 M | CL1: KP 50+ M | CM1: NP Unknown Age F | CN1: NP < 1 F | CO1: NP 1-4 F | CP1: NP 5-9 F | CQ1: NP 10-14 F | CR1: NP 15-19 F | CS1: NP 20-24 F | CT1: NP 25-29 F | CU1: NP 30-34 F | CV1: NP 35-39 F | CW1: NP 40-44 F | CX1: NP 45-49 F | CY1: NP 50+ F | CZ1: NP Unknown Age M | DA1: NP < 1 M | DB1: NP 1-4 M | DC1: NP 5-9 M | DD1: NP 10-14 M | DE1: NP 15-19 M | DF1: NP 20-24 M | DG1: NP 25-29 M | DH1: NP 30-34 M | DI1: NP 35-39 M | DJ1: NP 40-44 M | DK1: NP 45-49 M | DL1: NP 50+ M | DM1: NN Unknown Age F | DN1: NN < 1 F | DO1: NN 1-4 F | DP1: NN 5-9 F | DQ1: NN 10-14 F | DR1: NN 15-19 F | DS1: NN 20-24 F | DT1: NN 25-29 F | DU1: NN 30-34 F | DV1: NN 35-39 F | DW1: NN 40-44 F | DX1: NN 45-49 F | DY1: NN 50+ F | DZ1: NN Unknown Age M | EA1: NN < 1 M | EB1: NN 1-4 M | EC1: NN 5-9 M | ED1: NN 10-14 M | EE1: NN 15-19 M | EF1: NN 20-24 M | EG1: NN 25-29 M | EH1: NN 30-34 M | EI1: NN 35-39 M | EJ1: NN 40-44 M | EK1: NN 45-49 M | EL1: NN 50+ M | EM1: DN 1-4 F | EN1: DN 5-9 F | EO1: DN 10-14 F | EP1: DN 1-4 M | EQ1: DN 5-9 M | ER1: DN 10-14 M | ES1: ART High Volume | ET1: HTC High Volume | EU1: PMTCT High Volume
A350: =A2 -> 0 | B350: USAID Tujenge Jamii | C350: USAID Tujenge Jamii | D350: USAID Tujenge Jamii | E350: 11111 | F350: DSD | G350: =SUM(G2:G349) -> 0 | H350: =SUM(H2:H349) -> 0 | I350: =SUM(I2:I349) -> 0 | J350: =SUM(J2:J349) -> 0 | K350: =SUM(K2:K349) -> 0 | L350: =SUM(L2:L349) -> 0 | M350: =SUM(M2:M349) -> 0 | N350: =SUM(N2:N349) -> 0 | ... ER350: =SUM(ER2:ER349) -> 0 | ES350: 1 | ET350: 1 | EU350: 1

Sheet HTS_SELF
A1: period | B1: County | C1: sub_county | D1: Facility | E1: MFLCode | F1: Support Type | G1: Numerator | H1: Directly Ass Unknown Age F | I1: Directly Ass 10-14 F | J1: Directly Ass 15-19 F | K1: Directly Ass 20-24 F | L1: Directly Ass 25-29 F | M1: Directly Ass 30-34 F | N1: Directly Ass 35-39 F | O1: Directly Ass 40-44 F | P1: Directly Ass 45-49 F | Q1: Directly Ass 50+ F | R1: Directly Ass Unknown Age M | S1: Directly Ass 10-14 M | T1: Directly Ass 15-19 M | U1: Directly Ass 20-24 M | V1: Directly Ass 25-29 M | W1: Directly Ass 30-34 M | X1: Directly Ass 35-39 M | Y1: Directly Ass 40-44 M | Z1: Directly Ass 45-49 M | AA1: Directly Ass 50+ M | AB1: Unass Dissagg Unknown Age F | AC1: Unass Dissagg 10-14 F | AD1: Unass Dissagg 15-19 F | AE1: Unass Dissagg 20-24 F | AF1: Unass Dissagg 25-29 F | AG1: Unass Dissagg 30-34 F | AH1: Unass Dissagg 35-39 F | AI1: Unass Dissagg 40-44 F | AJ1: Unass Dissagg 45-49 F | AK1: Unass Dissagg 50+ F | AL1: Unass Dissagg Unknown Age M | AM1: Unass Dissagg 10-14 M | AN1: Unass Dissagg 15-19 M | AO1: Unass Dissagg 20-24 M | AP1: Unass Dissagg 25-29 M | AQ1: Unass Dissagg 30-34 M | AR1: Unass Dissagg 35-39 M | AS1: Unass Dissagg 40-44 M | AT1: Unass Dissagg 45-49 M | AU1: Unass Dissagg 50+ M | AV1: Unknown Sex | AW1: Unass selftes kit - Self | AX1: Unass selftes kit - Sex Partner | AY1: Unass selftes kit -Caregiver For the Child | AZ1: Unass selftes kit -Other | BA1: ART High Volume | BB1: HTC High Volume | BC1: PMTCT High Volume
A350: =A2 -> 0 | B350: USAID Tujenge Jamii | C350: USAID Tujenge Jamii | D350: USAID Tujenge Jamii | E350: 11111 | F350: DSD | G350: =SUM(G2:G349) -> 0 | H350: =SUM(H2:H349) -> 0 | I350: =SUM(I2:I349) -> 0 | J350: =SUM(J2:J349) -> 0 | K350: =SUM(K2:K349) -> 0 | L350: =SUM(L2:L349) -> 0 | M350: =SUM(M2:M349) -> 0 | N350: =SUM(N2:N349) -> 0 | ... AZ350: =SUM(AZ2:AZ349) -> 0 | BA350: 1 | BB350: 1 | BC350: 1

Sheet PMTCT_STAT
A1: period | B1: County | C1: sub_county | D1: Facility | E1: MFLCode | F1: Support Type | G1: PMTCT STAT NUM | H1: KP Unkown F | I1: KP <10 F | J1: KP 10-14 F | K1: KP 15-19 F | L1: KP 20-24 F | M1: KP 25-29 F | N1: KP 30-34 F | O1: KP 35-39 F | P1: KP 40-44 F | Q1: KP 45-49 F | R1: KP 50+ F | S1: NP Unkown F | T1: NP <10 F | U1: NP 10-14 F | V1: NP 15-19 F | W1: NP 20-24 F | X1: NP 25-29 F | Y1: NP 30-34 F | Z1: NP 35-39 F | AA1: NP 40-44 F | AB1: NP 45-49 F | AC1: NP 50+ F | AD1: NN Unkown F | AE1: NN <10 F | AF1: NN 10-14 F | AG1: NN 15-19 F | AH1: NN 20-24 F | AI1: NN 25-29 F | AJ1: NN 30-34 F | AK1: NN 35-39 F | AL1: NN 40-44 F | AM1: NN 45-49 F | AN1: NN 50+ F | AO1: RN Unkown F | AP1: RN <10 F | AQ1: RN 10-14 F | AR1: RN 15-19 F | AS1: RN 20-24 F | AT1: RN 25-29 F | AU1: RN 30-34 F | AV1: RN 35-39 F | AW1: RN 40-44 F | AX1: RN 45-49 F | AY1: RN 50+ F | AZ1: Den Unkown F | BA1: Den <10 F | BB1: Den 10-14 F | BC1: Den 15-19 F | BD1: Den 20-24 F | BE1: Den 25-29 F | BF1: Den 30-34 F | BG1: Den 35-39 F | BH1: Den 40-44 F | BI1: Den 45-49 F | BJ1: Den 50+ F | BK1: ART High Volume | BL1: HTC High Volume | BM1: PMTCT High Volume
A350: =A2 -> 0 | B350: USAID Tujenge Jamii | C350: USAID Tujenge Jamii | D350: USAID Tujenge Jamii | E350: 11111 | F350: DSD | G350: =SUM(G2:G349) -> 0 | H350: =SUM(H2:H349) -> 0 | I350: =SUM(I2:I349) -> 0 | J350: =SUM(J2:J349) -> 0 | K350: =SUM(K2:K349) -> 0 | L350: =SUM(L2:L349) -> 0 | M350: =SUM(M2:M349) -> 0 | N350: =SUM(N2:N349) -> 0 | ... BJ350: =SUM(BJ2:BJ349) -> 0 | BK350: 1 | BL350: 1 | BM350: 1

Sheet PMTCT_EID
A1: period | B1: facility_name | C1: district_name | D1: county | E1: mfl_code | F1: SupportType | G1: eid_1st_test_0_2months | H1: eid_1st_test_2_12months | I1: eid_2nd_test_0_2months | J1: eid_2nd_test_2_12months | K1: eid_pos_0_2months | L1: eid_pos_2_12months | M1: eid_neg_0_2months | N1: eid_neg_2_12months | O1: eid_pos_0_2months_ART | P1: eid_pos_2_12months_ART | Q1: ART_highvolume | R1: HTC_highvolume | S1: PMTCT_highvolume
